2025-05-15 17:49:45,503 [INFO] spy.SPY003: Espía SPY003 inicializado en posición 40.745751°N, 73.952621°W
2025-05-15 17:49:45,506 [ERROR] spy.SPY003: Error en el espía SPY003: RabbitMQPublisher.__init__() got an unexpected keyword argument 'routing_key'
Traceback (most recent call last):
  File "C:\Users\alexb\Documents\UAX\2_Ing\Metodos Numericos\ULab\PythonProject\agents\spy.py", line 129, in run
    self.connect()
    ~~~~~~~~~~~~^^
  File "C:\Users\alexb\Documents\UAX\2_Ing\Metodos Numericos\ULab\PythonProject\agents\spy.py", line 48, in connect
    self.comm_client = CommunicationClient(
                       ~~~~~~~~~~~~~~~~~~~^
        host=config.RABBITMQ_HOST,
        ^^^^^^^^^^^^^^^^^^^^^^^^^^
    ...<4 lines>...
        routing_key="alerts"
        ^^^^^^^^^^^^^^^^^^^^
    )
    ^
TypeError: RabbitMQPublisher.__init__() got an unexpected keyword argument 'routing_key'
2025-05-15 17:49:45,507 [INFO] spy.SPY003: Espía SPY003 finalizado
2025-05-15 19:28:01,168 [INFO] spy.SPY003: Espía SPY003 inicializado en posición 40.740103°N, 74.001110°W
2025-05-15 19:28:01,169 [WARNING] spy.SPY003: Intento 1 de conexión fallido: RabbitMQPublisher.__init__() got an unexpected keyword argument 'routing_key'. Intentos restantes: 2
2025-05-15 19:28:03,169 [WARNING] spy.SPY003: Intento 2 de conexión fallido: RabbitMQPublisher.__init__() got an unexpected keyword argument 'routing_key'. Intentos restantes: 1
2025-05-15 19:28:05,170 [WARNING] spy.SPY003: Intento 3 de conexión fallido: RabbitMQPublisher.__init__() got an unexpected keyword argument 'routing_key'. Intentos restantes: 0
2025-05-15 19:28:07,171 [ERROR] spy.SPY003: No se pudo conectar al servidor después de varios intentos
2025-05-15 19:28:07,171 [ERROR] spy.SPY003: Error en el espía SPY003: No se pudo conectar al servidor
Traceback (most recent call last):
  File "C:\Users\alexb\Documents\UAX\2_Ing\Metodos Numericos\ULab\PythonProject\agents\spy.py", line 193, in run
    self.connect()
    ~~~~~~~~~~~~^^
  File "C:\Users\alexb\Documents\UAX\2_Ing\Metodos Numericos\ULab\PythonProject\agents\spy.py", line 90, in connect
    raise ConnectionError("No se pudo conectar al servidor")
ConnectionError: No se pudo conectar al servidor
2025-05-15 19:28:07,172 [INFO] spy.SPY003: Espía SPY003 finalizado
